File: TGAdata/Bl_Moisture and Mold Resistant Drywall/Gyp_70_BI_T1_Nitrogen.txt
CLOSED
Version	2.0
Language	English
Mode	TGA 1000 °C
Run	1
RunSerial	3694
Instrument	TGA Q50 V20.13 Build 39
Module	TGA
InstSerial	0050-0958
Operator	Chimezie
File	\\Chem2503227x015\ta\Data\TGA\Dr Sezer\Gyp_70_BI_T1_Nitrogen.001
FurnaceType	Standard
Sample	Gyp_70_BI_T1_Nitrogen
Size	10.0040	mg
ProcName	Ramp
Method	Ramp
Comment
Xcomment	Pan: Platinum
Xcomment	Gas1: Nitrogen
Xcomment	Gas2: Air
Xcomment	Balance Gas: Nitrogen 20.0 ml/min
Xcomment	Sample Gas: Nitrogen 20.0 ml/min
Text
Kcell	1.00000
TempCal	2	pts	23.30	23.50,363.56	353.85
InstCalDate	Weight Date 2024-06-24 07:59:50
Controls	Gas 1  Event Off  Sampling 0.5
Nsig	6
Sig1	Time (min)
Sig2	Temperature (°C)
Sig3	Weight (mg)
Sig4	Balance Purge Flow (mL/min)
Sig5	Sample Purge Flow (mL/min)
Sig6	Deriv. Weight (%/°C)
AirCoolTime	0.0 min
AutoAnalysis	Off
MacroFile
Date	2024-10-10
Time	12:41:13
OrgMethod	1: Ramp 70.00 °C/min to 900.00 °C
OrgFile	C:\TA\Data\TGA\Dr Sezer\Gyp_70_BI_T1_Nitrogen.001
StartOfData
.003733334	21.36480	10.00342	19.98314	20.02938	-.01794280
0.01250000	21.38063	10.00354	20.00414	20.00719	-.01793459
0.02916666	21.44196	10.00373	20.01774	19.99718	-.01790229
0.04583334	21.55048	10.00388	20.00708	20.03891	-.01784331
0.06250000	21.71231	10.00446	19.98185	20.00756	-.01751722
0.07916666	21.92172	10.00533	19.98849	19.99155	-.01747954
0.09583332	22.17751	10.00606	20.01773	19.99071	-.01720050
0.1125000	22.48052	10.00659	20.00003	19.98999	-.01683802
0.1291666	22.83028	10.00742	20.00416	20.00143	-.01629654
0.1458333	23.22250	10.00828	19.99656	19.99419	-.01569685
0.1625000	23.65564	10.00883	20.01456	19.98617	-.01506356
0.1791666	24.12664	10.00853	20.00669	19.98599	-.01393408
0.1958334	24.63066	10.00955	20.00849	20.01170	-.01331307
0.2125000	25.17422	10.01079	19.98509	19.99612	-.01229522
0.2291667	25.74638	10.01197	20.01091	19.97959	-.01176524
0.2458334	26.35204	10.01259	19.99522	19.99679	-.01086215
0.2625000	26.98291	10.01321	20.00001	20.01532	-8.3605E-3
0.2791667	27.64274	10.01347	19.99766	19.99774	-6.6228E-3
0.2958333	28.32625	10.01334	19.99783	20.00344	-4.7855E-3
0.3125000	29.03610	10.01321	20.00154	19.98558	-3.6878E-3
0.3291667	29.76814	10.01330	19.98727	20.01439	-1.7219E-3
0.3458333	30.52430	10.01355	19.98712	19.99551	-6.3257E-5
0.3625000	31.29484	10.01348	19.99226	20.00342	6.63041E-4
0.3791666	32.09035	10.01368	20.01130	19.98438	.001402444
0.3958334	32.90282	10.01310	20.00989	20.01503	.001751451
0.4125000	33.72934	10.01299	19.99067	19.99792	.002256746
0.4291667	34.57652	10.01262	19.99871	19.99668	.002457788
0.4458333	35.43834	10.01223	20.00869	19.98206	.002605136
0.4625000	36.31380	10.01222	19.99930	20.02052	.002821402
0.4791666	37.20586	10.01208	19.97658	19.99640	.002950026
0.4958334	38.10810	10.01132	20.01104	19.99918	.003087390
0.5125000	39.02595	10.01138	20.01184	19.99709	.003337576
0.5291666	39.95508	10.01153	20.00018	20.01260	.003354861
0.5458334	40.89505	10.01100	20.00059	19.99594	.003456722
0.5625000	41.85002	10.01031	20.01332	19.98360	.003619054
0.5791666	42.81022	10.00977	20.00868	19.97041	.003697537
0.5958334	43.78084	10.00930	20.00035	20.00382	.004085078
0.6125000	44.76622	10.00935	20.00388	19.99078	.004332528
0.6291666	45.75828	10.00918	19.99514	19.98924	.004055276
0.6458332	46.76030	10.00847	20.01804	19.99265	.003631164
0.6625000	47.76916	10.00798	20.00286	19.99640	.003350258
0.6791668	48.78226	10.00725	20.00041	20.00481	.003243590
0.6958332	49.80574	10.00711	20.00521	19.99188	.003102278
0.7125000	50.83308	10.00717	20.00802	19.98641	.002897311
0.7291668	51.87161	10.00694	20.00647	19.99031	.002786221
0.7458334	52.91418	10.00674	19.99412	20.00642	.002832360
0.7625000	53.96544	10.00631	19.99637	20.00335	.003029054
0.7791666	55.02316	10.00610	20.02550	19.99143	.003577562
0.7958334	56.07954	10.00561	19.99856	19.99519	.003694089
0.8125000	57.14788	10.00487	19.98806	20.01048	.003845390
0.8291666	58.22047	10.00470	19.99636	19.99274	.004059197
0.8458334	59.29703	10.00422	20.00564	20.00069	.004117167
0.8625000	60.37504	10.00358	20.00240	20.00381	.004068159
0.8791668	61.46168	10.00363	19.99542	20.00541	.003835053
0.8958332	62.55068	10.00287	19.99220	20.02158	.003970897
0.9125000	63.64414	10.00238	19.99914	20.00402	.003708954
0.9291668	64.73950	10.00188	20.01686	19.99994	.003401530
0.9458332	65.83980	10.00168	19.98044	20.00607	.003527294
0.9625000	66.94055	10.00106	19.98062	20.00912	.003110539
0.9791668	68.04749	10.00102	19.99687	19.99969	.002882135
0.9958332	69.15668	10.00079	19.98237	20.00398	.002786148
1.012500	70.26722	10.00035	20.00634	20.01034	.002745808
1.029167	71.38135	10.00006	20.00508	20.01750	.002840387
1.045834	72.49890	9.999901	20.01711	19.99092	.002912229
1.062500	73.61816	9.999609	20.02147	19.99674	.003097688
1.079166	74.73630	9.999116	19.98586	20.01192	.002975398
1.095833	75.85813	9.998658	19.99709	20.00266	.002860916
1.112500	76.98048	9.998456	20.01411	20.00041	.002746971
1.129167	78.10525	9.997986	20.01272	19.99635	.002406832
1.145834	79.23356	9.997832	19.99159	20.00805	.002075198
1.162500	80.35735	9.997662	19.98364	20.01227	.001888500
1.179167	81.48928	9.997360	20.01074	19.99080	.001901782
1.195833	82.61782	9.997296	20.02473	19.99132	.002019814
1.212500	83.75112	9.997318	20.00846	19.99622	.002372276
1.229166	84.88379	9.996853	19.98432	20.02832	.002822158
1.245833	86.01710	9.996503	20.00058	20.01300	.002921716
1.262500	87.14863	9.996042	20.00881	19.99887	.003026116
1.279167	88.28553	9.995648	19.99683	19.99755	.003195306
1.295834	89.42142	9.995000	19.98447	20.00336	.003088760
1.312500	90.55757	9.995072	19.99445	20.00413	.002954230
1.329166	91.69525	9.994945	20.01329	19.98455	.002576025
1.345833	92.83420	9.994205	20.02612	19.98575	.002508878
1.362500	93.97266	9.993993	19.97862	20.02031	.002496310
1.379167	95.11028	9.993582	19.97358	20.00600	.002665444
1.395834	96.24648	9.993863	20.01392	19.98558	.002836532
1.412500	97.38449	9.993266	20.00636	19.99021	.002999042
1.429167	98.52203	9.992792	20.01358	20.01971	.003403875
1.445833	99.65603	9.992611	19.97549	20.00152	.003745728
1.462500	100.7943	9.992203	19.99262	19.99941	.004298797
1.479166	101.9307	9.991444	20.00950	20.00104	.004557098
1.495833	103.0684	9.990858	19.98688	20.01637	.004825730
1.512500	104.2032	9.990526	20.00088	20.01045	.005006146
1.529167	105.3399	9.989864	20.00936	20.01371	.005191102
1.545834	106.4768	9.989090	20.01764	19.99117	.005291838
1.562500	107.6122	9.988501	20.00320	20.00410	.005568386
1.579166	108.7487	9.988124	19.99801	20.00338	.005976544
1.595833	109.8880	9.987291	19.99052	20.01655	.006420196
1.612500	111.0220	9.986641	20.01046	19.99786	.007238620
1.629167	112.1619	9.985790	20.00565	19.98087	.008269062
1.645834	113.2978	9.984860	19.99751	19.99750	.009633399
1.662500	114.4364	9.983951	19.98660	20.00969	0.01134126
1.679166	115.5727	9.982349	19.98741	20.00109	0.01349611
1.695834	116.7093	9.980969	19.99542	19.99266	0.01599529
1.712500	117.8449	9.979218	20.02477	19.98198	0.01848769
1.729166	118.9826	9.976830	20.00151	19.99208	0.02150087
1.745833	120.1222	9.974036	19.98517	19.99896	0.02498407
1.762500	121.2586	9.970975	19.99378	20.00761	0.02901919
1.779167	122.3918	9.968195	19.99926	19.99168	0.03323344
1.795834	123.5314	9.964257	19.98453	19.99448	0.03773042
1.812500	124.6681	9.959532	19.98564	20.01543	0.04256820
1.829166	125.8008	9.954202	19.98935	20.01252	0.04787583
1.845833	126.9355	9.948788	20.00953	19.98816	0.05355171
1.862500	128.0696	9.942242	20.02506	19.99090	0.05913150
1.879167	129.2067	9.935512	19.98702	20.00672	0.06457868
1.895834	130.3405	9.927705	19.98324	20.00031	0.06983814
1.912500	131.4743	9.919374	20.02509	19.98432	0.07516254
1.929166	132.6088	9.910334	19.99879	20.00491	0.08002346
1.945834	133.7425	9.900647	19.98134	20.00504	0.08491425
1.962500	134.8759	9.891225	19.97504	20.00104	0.08947548
1.979166	136.0119	9.880609	19.99374	19.99286	0.09395318
1.995833	137.1445	9.869988	19.99111	20.00503	0.09821791
2.012500	138.2756	9.858338	20.00075	20.00324	0.1025682
2.029167	139.4098	9.846424	19.99384	20.00336	0.1073681
2.045834	140.5461	9.833891	20.00105	20.01556	0.1115992
2.062500	141.6796	9.821303	20.00079	19.98634	0.1157953
2.079166	142.8127	9.808101	20.01620	20.00644	0.1200088
2.095833	143.9454	9.793426	20.00505	20.00984	0.1250952
2.112500	145.0790	9.779532	20.00437	20.00572	0.1334545
2.129166	146.2139	9.764993	20.01702	20.00225	0.1439053
2.145833	147.3491	9.749222	20.02258	19.98910	0.1539621
2.162500	148.4817	9.733126	19.97969	20.03306	0.1623974
2.179166	149.6173	9.710876	19.98896	19.99740	0.1697313
2.195834	150.7534	9.687834	19.98997	19.99016	0.1751466
2.212500	151.8827	9.667398	20.01030	19.99449	0.1782015
2.229167	153.0181	9.648270	20.00475	19.99501	0.1790258
2.245834	154.1539	9.628876	19.98009	20.00272	0.1771633
2.262500	155.2901	9.608957	20.00336	19.99334	0.1756126
2.279167	156.4234	9.588875	20.00690	19.99369	0.1766355
2.295834	157.5590	9.568706	20.01452	19.99126	0.1790575
2.312500	158.6934	9.548556	19.99524	20.00220	0.1814620
2.329166	159.8285	9.528407	19.99229	20.02898	0.1838821
2.345833	160.9637	9.506936	20.00504	20.00950	0.1868268
2.362500	162.0970	9.485187	20.01577	19.99702	0.1900691
2.379166	163.2331	9.463889	19.97800	20.00449	0.1935953
2.395833	164.3694	9.441856	19.99722	20.00156	0.1970364
2.412500	165.5034	9.419149	19.99451	19.98636	0.2000576
2.429166	166.6372	9.396172	19.99182	19.98848	0.2030211
2.445834	167.7723	9.372745	19.98864	20.00775	0.2058254
2.462500	168.9098	9.349156	19.99538	19.99776	0.2082906
2.479167	170.0426	9.325301	19.99954	19.99785	0.2105328
2.495834	171.1789	9.300970	20.00760	19.99340	0.2127736
2.512500	172.3158	9.277294	19.99937	20.00164	0.2149990
2.529167	173.4520	9.252680	19.99278	19.99766	0.2172059
2.545834	174.5891	9.227756	19.99575	20.00469	0.2192663
2.562500	175.7242	9.202414	20.00262	19.99012	0.2212086
2.579166	176.8612	9.177176	19.99912	19.99660	0.2232806
2.595833	177.9970	9.151512	19.98141	20.00406	0.2252028
2.612500	179.1337	9.126001	19.97568	20.00224	0.2267801
2.629166	180.2716	9.100330	19.99654	20.01039	0.2280997
2.645833	181.4092	9.074256	20.00346	19.99636	0.2293446
2.662500	182.5469	9.047558	19.97935	20.00192	0.2305384
2.679166	183.6833	9.021305	20.00268	20.00731	0.2315975
2.695834	184.8203	8.994974	20.00624	19.99734	0.2322215
2.712500	185.9568	8.968689	19.99707	19.99716	0.2324149
2.729167	187.0968	8.941861	19.99970	20.01054	0.2327058
2.745834	188.2344	8.915368	19.99003	19.99711	0.2335327
2.762500	189.3706	8.888845	20.00502	19.99075	0.2345616
2.779167	190.5083	8.862828	20.00226	19.98747	0.2354437
2.795834	191.6475	8.835649	19.99605	19.98582	0.2363041
2.812500	192.7872	8.808314	19.99809	19.99702	0.2368810
2.829166	193.9275	8.780866	20.01020	20.00053	0.2369423
2.845833	195.0685	8.753976	19.99310	19.97877	0.2368140
2.862500	196.2022	8.726629	19.99579	20.00800	0.2358532
2.879166	197.3424	8.699972	19.98823	20.00748	0.2346201
2.895833	198.4831	8.673736	19.99422	20.00072	0.2332449
2.912500	199.6214	8.646978	20.00908	19.99202	0.2320367
2.929166	200.7586	8.620657	20.00693	20.01936	0.2305241
2.945834	201.9011	8.594398	19.97558	20.01050	0.2292389
2.962500	203.0395	8.568215	19.99588	19.99426	0.2278728
2.979167	204.1796	8.542220	19.99715	19.95908	0.2262028
2.995834	205.3218	8.516648	20.00118	20.00570	0.2242476
3.012500	206.4612	8.491072	19.99319	19.99701	0.2220466
3.029167	207.6023	8.465824	20.00481	20.00517	0.2192515
3.045834	208.7453	8.440543	20.00459	19.98546	0.2161855
3.062500	209.8856	8.416076	20.02695	19.99684	0.2128645
3.079166	211.0247	8.391789	19.99170	20.02099	0.2090888
3.095833	212.1673	8.368420	19.99353	20.00191	0.2051408
3.112500	213.3109	8.345191	20.01276	19.98883	0.2009313
3.129166	214.4546	8.322175	19.99682	20.01624	0.1964302
3.145833	215.5955	8.300056	19.97145	20.00372	0.1915679
3.162500	216.7342	8.278318	19.98939	20.01064	0.1865973
3.179166	217.8778	8.256878	20.00869	19.99657	0.1812217
3.195834	219.0201	8.236703	20.00219	20.00642	0.1752430
3.212500	220.1627	8.217218	19.98540	19.99927	0.1687366
3.229167	221.3045	8.198003	19.99050	19.99304	0.1618128
3.245834	222.4488	8.179478	20.00506	20.00178	0.1546536
3.262500	223.5895	8.162208	19.99294	19.98326	0.1473029
3.279167	224.7328	8.146079	20.01185	19.98594	0.1390669
3.295833	225.8764	8.130515	19.99229	20.00713	0.1300073
3.312500	227.0195	8.115736	20.01943	19.99606	0.1202146
3.329167	228.1606	8.102093	20.00008	19.99862	0.1097239
3.345833	229.3062	8.090190	19.97984	20.00233	0.09884915
3.362500	230.4516	8.079410	19.98998	20.01504	0.08754831
3.379166	231.5949	8.070094	20.00426	20.01409	0.07616324
3.395833	232.7394	8.062476	19.99405	20.00697	0.06547090
3.412500	233.8833	8.055849	19.99566	20.02772	0.05579590
3.429166	235.0277	8.050064	19.99176	20.01736	0.04748866
3.445834	236.1722	8.045650	20.01218	19.98912	0.04036878
3.462500	237.3196	8.041609	20.01043	20.00673	0.03450770
3.479167	238.4634	8.038445	20.00822	20.00864	0.02968581
3.495834	239.6098	8.035043	19.98349	19.98358	0.02569758
3.512500	240.7564	8.032637	19.99823	20.00498	0.02242551
3.529167	241.9016	8.030274	19.99269	20.00080	0.01962933
3.545833	243.0502	8.028120	20.00986	19.99625	0.01751016
3.562500	244.1953	8.026293	20.00020	19.99422	0.01553510
3.579167	245.3414	8.025000	19.99251	19.99128	0.01388242
3.595833	246.4888	8.023606	20.00395	19.99636	0.01236557
3.612500	247.6358	8.021908	20.01668	20.00799	0.01099035
3.629166	248.7834	8.020740	19.98696	19.99982	.009773111
3.645833	249.9338	8.019736	20.00417	20.00708	.008965580
3.662500	251.0804	8.018946	20.01151	20.00558	.008286587
3.679166	252.2268	8.018155	20.00663	20.00013	.007659240
3.695834	253.3753	8.017463	19.97754	19.99612	.007322076
3.712500	254.5270	8.016465	19.98941	20.01351	.007159169
3.729167	255.6748	8.015492	20.01301	19.99445	.007041610
3.745834	256.8236	8.014618	20.00095	19.99850	.006570869
3.762500	257.9697	8.014008	19.99040	20.01249	.006135453
3.779167	259.1203	8.013380	20.00568	19.98774	.005633020
3.795833	260.2689	8.012534	20.01299	19.98362	.005255718
3.812500	261.4160	8.012374	20.01638	20.00154	.004949848
3.829167	262.5680	8.011840	20.01282	19.99929	.004695606
3.845833	263.7179	8.011169	20.01684	19.99223	.004496722
3.862500	264.8685	8.010438	19.99988	20.00112	.004411832
3.879166	266.0192	8.010040	20.01694	20.00215	.004507112
3.895833	267.1694	8.009692	19.99720	19.99259	.003821176
3.912500	268.3176	8.009234	20.00905	20.00272	.002340316
3.929166	269.4698	8.008620	20.00057	19.99564	8.57959E-4
3.945834	270.6213	8.008110	20.02068	19.99785	-2.4554E-4
3.962500	271.7705	8.008426	19.97455	19.99566	-9.2201E-4
3.979167	272.9193	8.009659	19.97726	20.00230	-1.0790E-3
3.995834	274.0717	8.010166	20.01927	19.99663	-1.1566E-3
4.012500	275.2236	8.010060	20.00181	19.99616	-1.0743E-3
4.029167	276.3732	8.009870	19.96968	20.00440	-1.0913E-4
4.045833	277.5274	8.009197	19.99038	19.99994	.001249708
4.062500	278.6765	8.009144	20.00731	19.98761	.002098031
4.079167	279.8297	8.009742	19.99246	20.00662	.002786007
4.095833	280.9822	8.009162	20.00506	20.00414	.003214499
4.112500	282.1368	8.008487	19.99359	19.99759	.003705337
4.129166	283.2881	8.007978	20.02024	20.01161	.004246696
4.145834	284.4435	8.007100	20.01358	19.98752	.004454643
4.162500	285.5952	8.006750	20.00012	19.99535	.003784306
4.179167	286.7516	8.006090	19.99173	19.98450	.002967114
4.195833	287.9032	8.005769	20.00483	20.00833	.002623264
4.212500	289.0560	8.005810	20.00057	20.00122	.002413885
4.229166	290.2075	8.005816	19.99469	20.00476	.002342312
4.245834	291.3595	8.005879	19.99913	19.98880	.002619384
4.262500	292.5152	8.005093	19.98090	20.01412	.002973278
4.279167	293.6711	8.004410	20.01662	19.97362	.003462922
4.295833	294.8244	8.004426	20.01004	19.99627	.003920645
4.312500	295.9784	8.003588	19.98684	20.00151	.004455350
4.329167	297.1318	8.003269	19.98832	20.00709	.004654625
4.345833	298.2878	8.002915	19.97994	19.99760	.004580740
4.362500	299.4435	8.002344	19.99596	19.99436	.004780496
4.379166	300.5972	8.001462	19.99460	19.99663	.004292334
4.395834	301.7522	8.000518	19.98991	20.00992	.003726086
4.412500	302.9082	8.000665	19.99382	19.99047	.003085680
4.429167	304.0640	7.999938	20.00935	19.99442	.002573540
4.445833	305.2203	8.000199	20.00102	20.00311	.002148195
4.462500	306.3757	8.000172	19.98649	19.99647	.002056510
4.479166	307.5336	8.000082	19.99260	20.00532	.002419986
4.495834	308.6888	7.999380	20.00920	19.98435	.002510731
4.512500	309.8452	7.998935	20.00066	19.99701	.003124563
4.529167	311.0042	7.998579	19.99732	20.00061	.003299246
4.545833	312.1628	7.998194	20.02297	20.01141	.003055130
4.562500	313.3205	7.998139	19.99546	20.00030	.004018912
4.579167	314.4763	7.997268	20.00284	20.00266	.008639179
4.595833	315.6336	7.997260	19.99831	19.99572	0.01560674
4.612500	316.7908	7.997407	19.98211	19.99937	0.02210272
4.629166	317.9484	7.995318	20.01678	20.01325	0.02771149
4.645834	319.1056	7.988379	20.00713	19.98216	0.03139541
4.662500	320.2646	7.981110	19.98954	19.99542	0.03299339
4.679167	321.4235	7.977488	20.01145	20.00036	0.03180101
4.695833	322.5847	7.974228	20.00733	20.00428	0.02716102
4.712500	323.7410	7.971978	20.00266	19.99712	0.02004151
4.729166	324.8983	7.970515	19.99554	20.00690	0.01375809
4.745834	326.0568	7.969464	19.98200	20.00525	.009745326
4.762500	327.2173	7.968920	20.00827	19.99834	.006605636
4.779167	328.3756	7.968310	19.97991	19.99082	.004837424
4.795833	329.5351	7.967981	20.01485	20.00536	.003947575
4.812500	330.6921	7.967696	19.97884	19.99451	.003646237
4.829167	331.8534	7.967966	20.01678	20.01094	.003541074
4.845833	333.0123	7.966964	20.00860	20.01039	.003675060
4.862500	334.1721	7.966489	19.99800	19.99750	.004112238
4.879166	335.3326	7.965805	19.98312	20.01240	.004623194
4.895834	336.4934	7.965610	20.00601	20.00323	.005021118
4.912500	337.6548	7.964970	19.99862	19.98438	.004675858
4.929167	338.8144	7.964163	19.99840	19.98891	.004328876
4.945833	339.9799	7.963580	20.00516	20.00216	.004028108
4.962500	341.1409	7.963111	20.00362	19.99646	.003753700
4.979166	342.3018	7.962780	19.99378	19.99941	.003206918
4.995834	343.4652	7.962710	20.00179	19.99875	.002633525
5.012500	344.6291	7.962282	19.98804	19.99955	.002396500
5.029167	345.7888	7.961994	19.99914	20.01945	.002593738
5.045833	346.9526	7.961758	20.01143	19.99636	.002740740
5.062500	348.1116	7.961594	19.99052	20.00595	.002973716
5.079167	349.2763	7.961196	20.00288	20.00669	.003294440
5.095833	350.4387	7.960422	20.00620	20.01589	.003832640
5.112500	351.6027	7.960381	20.00777	19.98606	.004046032
5.129166	352.7620	7.959918	19.99830	20.00379	.003999163
5.145834	353.9278	7.959210	19.98848	20.00587	.003499520
5.162500	355.0915	7.958270	19.99070	20.00630	.002914796
5.179167	356.2536	7.958258	20.01266	20.00326	.002757052
5.195833	357.4148	7.958110	20.00000	19.99583	.002468004
5.212500	358.5750	7.958204	19.99585	20.00338	.002091201
5.229166	359.7368	7.958070	19.98379	19.98087	.002050098
5.245834	360.8990	7.957490	20.00856	20.00299	.002712990
5.262500	362.0600	7.957158	19.99640	20.01089	.003376461
5.279168	363.2196	7.956925	20.01363	20.00402	.004094844
5.295832	364.3794	7.956454	19.98147	20.00527	.004486734
5.312500	365.5400	7.955579	20.01652	19.97659	.004655270
5.329168	366.6997	7.955002	19.99982	19.99773	.004725516
5.345832	367.8576	7.954366	20.00584	19.99448	.004648625
5.362500	369.0150	7.953936	19.97961	20.00771	.004350659
5.379166	370.1742	7.953316	20.00348	20.00386	.003998162
5.395834	371.3330	7.953042	20.00308	20.00152	.003927567
5.412500	372.4918	7.952728	20.00462	19.99901	.003924485
5.429168	373.6500	7.952382	19.99572	20.01625	.003990266
5.445832	374.8112	7.951890	20.00327	19.99750	.003755004
5.462500	375.9738	7.951232	20.00766	20.00040	.003400648
5.479166	377.1310	7.950634	19.99428	19.99361	.003192253
5.495834	378.2925	7.950171	19.99838	19.99567	.003329790
5.512500	379.4522	7.950218	20.00354	19.99289	.003909059
5.529168	380.6124	7.950328	20.00761	20.00010	.004287131
5.545832	381.7724	7.949739	20.00441	20.00288	.004434727
5.562500	382.9343	7.948851	20.00873	19.99424	.004532053
5.579168	384.0947	7.947419	19.99016	20.01506	.004842034
5.595832	385.2564	7.946944	19.99313	20.00714	.004787363
5.612500	386.4179	7.946974	19.99958	19.99698	.004220280
5.629166	387.5794	7.946765	20.00943	19.99777	.003620981
5.645834	388.7412	7.946059	19.98592	20.01134	.003196115
5.662500	389.9028	7.945826	19.98594	19.99516	.003441680
5.679168	391.0637	7.945563	20.00316	19.99856	.003709828
5.695832	392.2280	7.944929	20.02110	20.00198	.003921690
5.712500	393.3894	7.944442	20.00018	20.01162	.003929182
5.729166	394.5508	7.943874	19.97914	20.00529	.003988916
5.745834	395.7114	7.943690	19.99381	20.00500	.004281231
5.762500	396.8729	7.943047	20.01127	20.00355	.004172538
5.779168	398.0356	7.942536	20.00716	20.00685	.004066925
5.795832	399.1963	7.942218	19.99175	19.99084	.003845570
5.812500	400.3601	7.941260	20.00919	19.99941	.003873248
5.829168	401.5226	7.941189	20.00511	19.95651	.004008186
5.845832	402.6833	7.940689	20.02068	20.01300	.004435092
5.862500	403.8456	7.940503	19.98598	20.00554	.004804674
5.879166	405.0130	7.939978	19.99432	19.99984	.004775562
5.895834	406.1750	7.939031	20.00035	19.99691	.004629430
5.912500	407.3370	7.938001	20.00362	20.00517	.004305853
5.929168	408.5006	7.937546	19.99468	20.00208	.004040231
5.945832	409.6623	7.937218	19.99092	20.01225	.003639595
5.962500	410.8274	7.937442	20.00699	20.00276	.003054478
5.979166	411.9897	7.937153	19.99996	19.99816	.002804856
5.995834	413.1528	7.936658	20.01024	20.00840	.003123272
6.012500	414.3170	7.936072	19.99742	19.99226	.003881216
6.029168	415.4795	7.935894	19.98100	20.00130	.004820202
6.045832	416.6425	7.935268	20.01232	19.99772	.005359340
6.062500	417.8060	7.934638	19.99278	19.99861	.005631007
6.079168	418.9713	7.933780	19.97474	20.00658	.005828120
6.095832	420.1372	7.932797	19.99319	19.99926	.006110668
6.112500	421.3012	7.932088	20.01101	19.98996	.006269600
6.129166	422.4648	7.931505	20.00275	20.00271	.006354287
6.145834	423.6296	7.930968	20.00329	20.02152	.006196174
6.162500	424.7936	7.930255	19.99612	19.99544	.005942742
6.179168	425.9572	7.929334	19.99137	20.00215	.005809247
6.195832	427.1221	7.928412	20.00044	20.00654	.005744613
6.212500	428.2852	7.927968	19.99109	19.98907	.005553272
6.229166	429.4530	7.927500	19.99402	20.00922	.005186736
6.245834	430.6197	7.926905	19.99559	19.99703	.004998394
6.262500	431.7826	7.926220	19.99552	19.99529	.005035604
6.279168	432.9490	7.925690	19.99806	19.98878	.005212274
6.295832	434.1172	7.925345	19.99776	20.01004	.005205826
6.312500	435.2857	7.924490	20.01031	20.00062	.005251998
6.329168	436.4500	7.923642	19.99619	20.00232	.005307422
6.345832	437.6145	7.923105	20.01502	19.99488	.005297758
6.362500	438.7810	7.922801	19.98308	20.00707	.005111775
6.379166	439.9482	7.922074	19.98956	19.99795	.004627147
6.395834	441.1140	7.921205	20.00262	19.99564	.003878921
6.412500	442.2818	7.920776	20.01639	19.99684	.003527672
6.429168	443.4464	7.920550	19.98434	20.01621	.003437292
6.445832	444.6150	7.920200	20.00030	20.00395	.002978667
6.462500	445.7806	7.920460	19.99894	19.97877	.002518264
6.479166	446.9470	7.919888	20.01159	19.99738	.002292808
6.495834	448.1157	7.919089	20.01188	20.01504	.002485117
6.512500	449.2832	7.919028	20.00308	19.99711	.002670000
6.529166	450.4506	7.918975	20.00150	20.00039	.002848375
6.545832	451.6188	7.918952	20.01188	19.98872	.002485256
6.562500	452.7866	7.918174	20.00781	19.99211	.002154134
6.579168	453.9549	7.917731	19.99479	20.00470	.002280121
6.595834	455.1241	7.917462	19.99464	20.01067	.002534859
6.612500	456.2924	7.917532	19.99906	19.99585	.002818565
6.629166	457.4606	7.917401	20.01233	19.99720	.002884735
6.645834	458.6317	7.917038	20.00402	20.00957	.003065442
6.662500	459.8004	7.916425	19.99250	20.01313	.003237141
6.679168	460.9688	7.915779	20.01252	20.02238	.003253891
6.695832	462.1387	7.915331	19.99987	19.98912	.003101489
6.712500	463.3084	7.915058	20.00996	20.00906	.002642980
6.729166	464.4774	7.914897	19.98726	20.01102	.002009783
6.745834	465.6447	7.914880	20.00506	20.00966	.001491140
6.762500	466.8154	7.914534	20.00659	20.00715	.001003564
6.779166	467.9824	7.914406	20.00332	20.01178	9.90108E-4
6.795832	469.1520	7.914482	19.97644	20.01239	.001232455
6.812500	470.3234	7.914310	19.99740	19.99351	.001718924
6.829168	471.4930	7.914546	20.01272	19.99382	.002159436
6.845834	472.6629	7.913960	19.99669	20.00931	.002624865
6.862500	473.8342	7.913534	19.99811	20.00884	.003123072
6.879166	475.0044	7.912896	19.99689	19.99395	.003448704
6.895834	476.1739	7.912402	20.00866	19.98443	.003606672
6.912500	477.3443	7.912174	20.00744	20.01444	.003617422
6.929168	478.5138	7.911782	20.00018	19.99122	.003975950
6.945832	479.6856	7.911319	19.98614	20.00495	.004436761
6.962500	480.8534	7.911112	20.00454	20.00780	.004905350
6.979166	482.0254	7.910420	20.01250	20.00483	.005387963
6.995834	483.1960	7.909366	19.99141	20.00603	.005472460
7.012500	484.3665	7.908489	19.99722	20.00691	.005566568
7.029166	485.5390	7.907986	19.98266	20.01024	.005257297
7.045832	486.7104	7.907307	20.00878	19.99280	.004467385
7.062500	487.8822	7.907099	20.00680	20.01572	.003481262
7.079168	489.0546	7.906361	19.99933	19.99774	.002646650
7.095834	490.2256	7.906322	19.99537	20.04656	.002299229
7.112500	491.3967	7.906160	20.00825	20.01126	.002156943
7.129166	492.5670	7.906110	20.00606	19.99351	.001980094
7.145834	493.7416	7.906151	19.97774	19.99984	9.95780E-4
7.162500	494.9130	7.905557	19.98672	19.99998	-7.8946E-4
7.179168	496.0830	7.904919	20.01063	19.98551	-2.5978E-3
7.195832	497.2560	7.905061	20.00529	20.00140	-4.7463E-3
7.212500	498.4297	7.905968	19.99918	20.01130	-6.1720E-3
7.229166	499.6008	7.908184	19.98893	20.01037	-7.1325E-3
7.245834	500.7732	7.908976	19.99509	19.99714	-7.4042E-3
7.262500	501.9444	7.910584	20.00752	19.98546	-6.0008E-3
7.279166	503.1166	7.910645	20.00228	20.00549	-3.3445E-3
7.295832	504.2912	7.910720	19.98395	20.00816	-3.8523E-4
7.312500	505.4634	7.911216	20.00391	20.00413	.001554631
7.329168	506.6363	7.910270	20.00421	19.99300	.003070589
7.345834	507.8110	7.909194	20.00370	20.00114	.003592784
7.362500	508.9835	7.908679	19.98803	19.99706	.004099862
7.379166	510.1584	7.908384	20.01459	19.98340	.004222945
7.395834	511.3281	7.908163	19.99999	19.99453	.003580141
7.412500	512.5000	7.907980	19.99975	19.98489	.002670400
7.429168	513.6761	7.907105	19.99944	20.02024	.002096130
7.445832	514.8496	7.906926	19.99605	20.00762	.001664696
7.462500	516.0206	7.906651	20.00355	19.99932	.001326141
7.479166	517.1959	7.906944	20.00081	20.00487	8.34526E-4
7.495834	518.3720	7.906934	19.99783	20.00900	1.69426E-4
7.512500	519.5406	7.906962	20.01538	20.01420	4.00127E-4
7.529166	520.7160	7.906749	20.02326	19.99335	.001150569
7.545832	521.8906	7.906792	20.00571	20.00349	.001937660
7.562500	523.0611	7.907001	19.99972	20.01008	.002521324
7.579168	524.2350	7.906293	19.99184	20.00812	.002821634
7.595834	525.4084	7.905289	20.01833	20.01109	.002817270
7.612500	526.5826	7.905022	19.99601	20.01147	.002799084
7.629166	527.7555	7.904682	19.99271	19.99611	.002520908
7.645834	528.9300	7.904639	19.99610	20.00245	.001644296
7.662500	530.1015	7.904694	19.99839	19.99288	9.85771E-4
7.679168	531.2747	7.904528	20.00706	20.00025	8.42628E-4
7.695832	532.4468	7.904365	19.98594	19.99335	6.87153E-4
7.712500	533.6223	7.904488	19.98846	20.00198	6.18301E-4
7.729166	534.7959	7.904239	20.00188	19.98763	5.23287E-4
7.745834	535.9695	7.904039	20.01069	19.99506	4.16671E-4
7.762500	537.1412	7.904157	19.99215	20.01806	4.94697E-4
7.779166	538.3144	7.904225	19.99579	20.01146	6.82118E-4
7.795832	539.4898	7.904251	20.01616	20.00074	8.97749E-4
7.812500	540.6652	7.904080	20.00223	20.01306	.001301800
7.829168	541.8398	7.903826	19.99745	20.00896	.001785780
7.845834	543.0156	7.903668	20.00570	20.00812	.002078328
7.862500	544.1921	7.903261	20.00775	20.00716	.002087222
7.879166	545.3672	7.902756	20.00156	20.00628	.001908013
7.895834	546.5434	7.902478	20.00135	19.99599	.001863789
7.912500	547.7176	7.902451	19.99863	19.99886	.001720824
7.929168	548.8934	7.902505	19.98878	19.99665	.001362491
7.945832	550.0688	7.902457	20.00235	19.98582	8.89549E-4
7.962500	551.2443	7.901885	20.00414	20.00629	6.46575E-4
7.979166	552.4168	7.901798	20.00480	20.00005	6.97146E-4
7.995834	553.5886	7.901892	19.99257	19.99051	9.95148E-4
8.012500	554.7651	7.902164	20.01932	19.98641	.001154558
8.029166	555.9400	7.902097	19.99976	20.00751	.001336416
8.045834	557.1137	7.901778	19.98092	20.01379	.001516385
8.062500	558.2912	7.901195	20.00458	19.99744	.001829488
8.079166	559.4618	7.901032	20.01354	19.99453	.002169350
8.095834	560.6384	7.900595	20.00564	20.01127	.002181002
8.112500	561.8150	7.900826	20.00359	19.99777	.001962422
8.129166	562.9889	7.900522	20.00421	19.98880	.001521343
8.145832	564.1630	7.900118	20.01514	19.98276	.001324720
8.162500	565.3373	7.899951	19.99544	19.99112	.001250034
8.179168	566.5118	7.899761	19.99354	20.00063	.001395472
8.195832	567.6853	7.899976	19.97642	20.00689	9.55198E-4
8.212500	568.8581	7.899824	19.99970	20.00027	6.16111E-4
8.229168	570.0351	7.899526	19.98662	19.99269	5.97786E-4
8.245834	571.2113	7.899200	20.00673	20.00148	6.22242E-4
8.262500	572.3868	7.899726	19.98050	19.99002	6.98023E-4
8.279166	573.5592	7.899626	20.02040	19.99540	4.10896E-4
8.295834	574.7349	7.899351	20.00592	19.99428	3.33837E-4
8.312500	575.9112	7.899293	19.98459	20.03352	4.56055E-4
8.329166	577.0832	7.899162	19.99845	19.99625	8.07016E-4
8.345834	578.2579	7.899494	20.00957	20.00038	.001018916
8.362500	579.4330	7.899168	20.01063	20.00270	.001554754
8.379166	580.6108	7.898919	19.99445	20.01897	.002043423
8.395832	581.7850	7.898824	19.99265	20.00072	.002150936
8.412500	582.9610	7.898500	19.98982	19.98870	.002220963
8.429168	584.1384	7.897540	20.00270	19.99598	.001962444
8.445832	585.3128	7.897330	20.00300	20.00892	.001677162
8.462500	586.4875	7.897708	19.99262	19.99813	.001347927
8.479168	587.6648	7.897616	20.00112	20.00769	7.94497E-4
8.495834	588.8404	7.897450	20.00319	19.99543	1.99751E-4
8.512500	590.0170	7.897345	19.97342	19.99128	1.59598E-4
8.529166	591.1924	7.897278	20.00702	20.01052	4.37719E-4
8.545834	592.3684	7.897421	19.99779	20.00716	6.94126E-4
8.562500	593.5448	7.897506	19.99749	19.99194	7.12381E-4
8.579166	594.7202	7.897352	19.99602	19.99946	6.88000E-4
8.595834	595.8979	7.897125	20.00885	20.00208	7.35716E-4
8.612500	597.0735	7.896638	19.99651	19.99309	.001066793
8.629166	598.2470	7.896800	20.01323	19.99305	.001349246
8.645832	599.4248	7.896919	20.00408	20.01249	.001224402
8.662500	600.6006	7.896908	19.99322	20.01099	.001047597
8.679168	601.7776	7.896375	20.00105	19.99523	9.32259E-4
8.695832	602.9524	7.895997	20.00148	20.00032	.001394304
8.712500	604.1272	7.896243	19.99235	20.00434	.001764102
8.729168	605.3037	7.896155	19.99994	19.99786	.001767803
8.745834	606.4802	7.896075	19.99896	20.01496	.001199692
8.762500	607.6549	7.895361	20.00204	20.00870	.001103206
8.779166	608.8305	7.895000	19.99967	20.00034	.001333970
8.795834	610.0061	7.894966	19.98945	20.00496	.001264715
8.812500	611.1840	7.895681	19.99383	19.99899	.001577486
8.829166	612.3604	7.895228	20.00128	20.00367	.002442299
8.845834	613.5385	7.894864	20.01311	19.99946	.003159968
8.862500	614.7152	7.894828	19.99570	20.01241	.003921579
8.879166	615.8915	7.893975	20.01050	20.01097	.004741202
8.895832	617.0678	7.892278	20.00009	19.99504	.004713506
8.912500	618.2437	7.892280	20.00682	19.99170	.004523129
8.929168	619.4210	7.892094	19.99403	20.00539	.004152821
8.945832	620.5955	7.891375	20.00392	19.99354	.003337938
8.962500	621.7701	7.891166	19.99134	19.99931	.002373425
8.979168	622.9456	7.890810	20.00049	19.99516	.002358982
8.995834	624.1218	7.890662	20.00260	19.99916	.002174728
9.012500	625.2976	7.890391	19.98192	20.00692	.001573655
9.029166	626.4708	7.890402	19.99330	19.99508	.001297511
9.045834	627.6466	7.889893	19.99537	19.98813	.001062878
9.062500	628.8211	7.889739	20.00113	19.98595	.001448379
9.079166	629.9980	7.890178	20.00394	20.00271	.001698735
9.095834	631.1760	7.889942	20.00889	20.00246	.001823314
9.112500	632.3592	7.889868	19.99936	19.99280	.001754201
9.129166	633.5398	7.888762	20.01125	19.99638	.001847596
9.145832	634.7200	7.888570	19.98904	20.00218	.002232788
9.162500	635.8944	7.888722	19.98873	20.01697	.002272768
9.179168	637.0609	7.888620	20.00127	20.00557	.001983757
9.195832	638.2282	7.888462	19.99622	20.00333	.001502422
9.212500	639.3920	7.887971	20.01010	20.02066	.001269759
9.229168	640.5576	7.887597	19.97538	19.99637	.001295586
9.245834	641.7192	7.887780	19.99249	20.01384	.001468411
9.262500	642.8840	7.887569	20.00691	19.98840	.001461116
9.279166	644.0554	7.887804	19.98939	20.01047	.001286749
9.295834	645.2246	7.887563	20.00345	19.99993	.001238012
9.312500	646.3968	7.886868	19.99300	20.00310	.001536167
9.329166	647.5714	7.886858	20.01142	20.00699	.001780924
9.345834	648.7434	7.886804	19.99942	20.01116	.001920811
9.362500	649.9198	7.886726	20.00024	20.00665	.001653408
9.379166	651.0959	7.886374	19.98640	20.00881	.001412816
9.395832	652.2691	7.886020	19.99983	19.99436	.001378263
9.412500	653.4481	7.885910	20.00016	19.99235	.001353110
9.429168	654.6230	7.885970	20.00122	19.99236	.001255435
9.445832	655.8000	7.885653	20.01059	20.01117	.001168297
9.462500	656.9739	7.885674	20.00456	19.98989	.001098588
9.479168	658.1487	7.885522	20.00526	20.00070	.001212538
9.495834	659.3237	7.885445	19.99984	20.00512	.001428102
9.512500	660.4980	7.885026	19.98848	19.99734	.001148660
9.529166	661.6720	7.885004	20.01418	20.00119	7.75742E-4
9.545834	662.8470	7.884916	20.00110	19.98393	-1.9921E-4
9.562500	664.0204	7.884522	19.99756	19.99416	-1.4457E-3
9.579166	665.1931	7.884856	19.98281	20.00820	-2.1645E-3
9.595834	666.3655	7.885100	19.96986	20.00327	-2.2796E-3
9.612500	667.5384	7.886084	19.99896	19.99120	-2.1059E-3
9.629166	668.7174	7.887075	20.00194	20.02418	-1.8326E-3
9.645832	669.8913	7.886703	19.98812	20.00432	-1.4499E-3
9.662500	671.0651	7.886292	19.99451	20.00532	-6.3053E-4
9.679168	672.2414	7.886120	20.01756	19.99467	2.78117E-4
9.695832	673.4118	7.886120	19.99899	20.01072	.001148945
9.712500	674.5832	7.886781	19.99400	20.00410	.001326747
9.729168	675.7581	7.886200	20.00191	20.00219	.001384794
9.745834	676.9349	7.886150	20.00426	19.99536	.001570600
9.762500	678.1102	7.885366	19.99489	20.00057	.002055326
9.779166	679.2844	7.885132	19.99309	20.01303	.002585388
9.795834	680.4600	7.885108	19.99516	19.99595	.002330467
9.812500	681.6360	7.885024	20.00314	19.98645	.002151310
9.829166	682.8116	7.884540	19.99968	20.01566	.001737357
9.845834	683.9882	7.884093	19.98778	20.00056	.001714326
9.862500	685.1619	7.884192	19.99498	20.00514	.001692560
9.879166	686.3374	7.883999	20.00728	20.00444	.001469386
9.895832	687.5120	7.883939	20.00270	19.99803	.001364365
9.912500	688.6866	7.883566	20.00414	20.00989	.001461152
9.929168	689.8590	7.883487	20.00105	19.98908	.001859347
9.945832	691.0362	7.883556	19.99988	20.00158	.002373164
9.962500	692.2106	7.883020	19.99739	20.00564	.003250926
9.979168	693.3882	7.882732	19.98734	20.00131	.004007909
9.995834	694.5640	7.882345	19.97484	19.98175	.004684780
10.01250	695.7412	7.881648	19.99342	19.99515	.004997872
10.02917	696.9197	7.880543	20.00005	19.99327	.005022514
10.04583	698.0922	7.879870	20.00652	20.01447	.004929930
10.06250	699.2671	7.879358	19.99517	20.02349	.004860066
10.07917	700.4386	7.879239	20.00940	20.00091	.004782356
10.09583	701.6138	7.878575	20.02018	19.99064	.004811574
10.11250	702.7886	7.878256	20.00246	19.99939	.005234366
10.12917	703.9626	7.877532	19.99871	19.98419	.005799856
10.14583	705.1338	7.876730	20.00625	20.00884	.006448697
10.16250	706.3094	7.875728	20.01813	20.00443	.006805203
10.17917	707.4819	7.874802	19.99327	19.99610	.007265704
10.19583	708.6519	7.874134	20.00684	20.00318	.007212714
10.21250	709.8239	7.873194	19.99696	19.99948	.007063196
10.22917	710.9978	7.872490	20.00525	19.98706	.007129082
10.24583	712.1722	7.871339	20.02604	19.99776	.007321365
10.26250	713.3444	7.870800	19.99998	20.01531	.007519019
10.27917	714.5206	7.870174	19.99036	19.99645	.007469656
10.29583	715.6954	7.868975	20.01171	19.99629	.007354590
10.31250	716.8704	7.867926	20.00306	19.99472	.006937236
10.32917	718.0440	7.866972	20.00678	20.00765	.006973108
10.34583	719.2159	7.866344	19.99369	20.01673	.007382214
10.36250	720.3858	7.865668	20.00018	20.00052	.007820930
10.37917	721.5612	7.865274	20.00991	19.97708	.008510620
10.39583	722.7368	7.864250	19.99452	20.00572	.009122009
10.41250	723.9095	7.862490	19.99996	20.00987	.009809361
10.42917	725.0869	7.860992	19.98606	19.99928	0.01020937
10.44583	726.2615	7.859678	20.01880	19.99900	0.01063698
10.46250	727.4356	7.858880	19.99339	20.00242	0.01056601
10.47917	728.6103	7.857622	19.98856	20.00562	.009852799
10.49584	729.7844	7.856665	20.00192	19.99675	.009433585
10.51250	730.9600	7.855169	20.01804	19.98082	.009309174
10.52916	732.1303	7.853818	20.00316	20.00026	.009500984
10.54584	733.3043	7.853320	19.99260	20.00549	.009742576
10.56250	734.4764	7.852274	20.00204	20.00366	.009843563
10.57916	735.6499	7.851038	20.01548	19.99930	.009952050
10.59584	736.8230	7.849799	19.98729	19.98886	0.01018819
10.61250	737.9957	7.848243	19.98798	20.00737	0.01067548
10.62916	739.1680	7.847240	19.99217	19.99897	0.01084221
10.64583	740.3394	7.845798	19.99786	19.99770	0.01092259
10.66250	741.5129	7.844676	19.99404	19.99573	0.01083397
10.67917	742.6895	7.843386	19.97471	20.01200	0.01055470
10.69583	743.8610	7.842107	20.00811	19.99750	0.01067536
10.71250	745.0347	7.840619	20.00678	19.99039	0.01107720
10.72917	746.2089	7.839503	20.02038	20.00458	0.01162773
10.74584	747.3855	7.838624	20.00348	20.00136	0.01187080
10.76250	748.5618	7.837146	19.98988	20.00247	0.01198391
10.77916	749.7344	7.835058	20.01177	19.99438	0.01229490
10.79584	750.9074	7.833396	20.00152	19.99623	0.01281300
10.81250	752.0820	7.832266	19.99461	20.00722	0.01305812
10.82916	753.2551	7.831072	19.97508	20.00690	0.01294392
10.84584	754.4281	7.829345	19.99449	20.00467	0.01276452
10.86250	755.6003	7.827585	20.02191	20.00928	0.01282231
10.87916	756.7697	7.826290	20.00193	19.99503	0.01303024
10.89583	757.9405	7.824749	19.99627	20.00685	0.01312662
10.91250	759.1135	7.823105	19.99707	20.00784	0.01303443
10.92917	760.2861	7.821689	20.01142	20.00420	0.01295332
10.94583	761.4606	7.820198	19.99773	19.99173	0.01290470
10.96250	762.6391	7.818599	19.97611	20.00813	0.01291789
10.97917	763.8132	7.816968	20.00156	19.99713	0.01310040
10.99584	764.9874	7.815480	20.00412	20.00171	0.01359406
11.01250	766.1630	7.814234	20.01251	19.99815	0.01380017
11.02916	767.3386	7.812485	19.98905	19.99097	0.01409258
11.04584	768.5124	7.810703	20.00806	19.99913	0.01453638
11.06250	769.6862	7.808588	20.01732	20.00294	0.01501741
11.07916	770.8632	7.807266	20.00147	20.01069	0.01546955
11.09584	772.0361	7.805371	19.98580	19.97608	0.01572194
11.11250	773.2081	7.803380	20.00076	19.99516	0.01568757
11.12916	774.3835	7.801545	20.00464	19.98154	0.01613523
11.14583	775.5538	7.799706	19.99704	19.98522	0.01676278
11.16250	776.7266	7.797584	19.99556	19.99939	0.01685992
11.17917	777.8997	7.796147	19.99149	19.99864	0.01677579
11.19583	779.0720	7.793398	19.99378	19.99884	0.01670544
11.21250	780.2475	7.791368	19.99674	19.99003	0.01663816
11.22917	781.4205	7.789658	19.99697	20.01071	0.01638824
11.24584	782.5950	7.787861	19.98228	20.00769	0.01635449
11.26250	783.7665	7.786102	20.00110	20.00341	0.01584263
11.27916	784.9394	7.784009	20.01713	20.00690	0.01543939
11.29584	786.1138	7.782278	19.98720	20.00829	0.01524472
11.31250	787.2864	7.780212	19.99703	20.01420	0.01503390
11.32916	788.4595	7.778522	19.99672	19.99791	0.01473796
11.34584	789.6335	7.777216	20.00805	19.98228	0.01425927
11.36250	790.8085	7.775468	19.99825	20.00309	0.01365871
11.37916	791.9832	7.773748	19.99531	20.00709	0.01298308
11.39583	793.1538	7.772124	20.00860	19.99158	0.01245435
11.41250	794.3258	7.770634	20.00220	20.01084	0.01191584
11.42917	795.5008	7.769501	20.01430	19.99960	0.01132742
11.44583	796.6758	7.768228	19.97761	19.99625	0.01088159
11.46250	797.8462	7.767040	19.99894	19.99484	0.01057996
11.47917	799.0196	7.765984	19.99249	20.00380	0.01008513
11.49584	800.1952	7.764605	20.01036	19.98827	.009710043
11.51250	801.3696	7.763238	19.99694	20.00594	.009566172
11.52916	802.5424	7.761972	20.00814	20.01176	.009444134
11.54584	803.7116	7.761478	19.99190	20.01158	.009103759
11.56250	804.8870	7.760644	20.00600	19.98452	.008244068
11.57916	806.0630	7.759094	19.99956	20.01164	.007360544
11.59584	807.2337	7.757972	20.01895	20.00944	.006692088
11.61250	808.4036	7.757245	20.00351	20.01030	.006298060
11.62916	809.5750	7.757129	20.01347	20.00499	.005428500
11.64583	810.7482	7.756679	20.00710	19.99990	.004289320
11.66250	811.9187	7.756018	20.00006	19.99968	.003556100
11.67917	813.0890	7.755292	20.00961	19.98799	.003192583
11.69583	814.2600	7.755166	20.00167	20.01432	.003028447
11.71250	815.4331	7.755049	19.99257	20.00570	.002622044
11.72917	816.6032	7.754768	19.98936	20.00648	.002437298
11.74584	817.7749	7.754508	20.00521	20.01031	.002907874
11.76250	818.9504	7.754153	20.00214	19.98765	.004403278
11.77916	820.1303	7.754070	20.00307	19.99859	.005971948
11.79584	821.3012	7.753510	20.00209	19.99172	.006971776
11.81250	822.4728	7.752292	19.98756	20.00137	.007466139
11.82916	823.6488	7.750361	20.00988	19.99295	.007442870
11.84584	824.8207	7.749075	20.00148	19.99173	.007069778
11.86250	825.9868	7.748668	19.99264	20.01266	.005976472
11.87916	827.1447	7.748360	19.99630	20.01426	.004132785
11.89583	828.3081	7.748222	20.00465	19.98768	.002139853
11.91250	829.4749	7.747840	20.00929	19.99913	.001015094
11.92917	830.6461	7.747620	20.00689	19.99232	9.40446E-4
11.94583	831.8181	7.747995	20.01239	19.99998	.001126034
11.96250	832.9960	7.748261	19.98921	20.00730	8.68933E-4
11.97917	834.1775	7.748074	19.99876	19.98608	-1.7225E-4
11.99584	835.3614	7.747281	20.01274	20.00876	-5.6492E-4
12.01250	836.5366	7.746848	19.99534	19.99690	-2.8120E-4
12.02916	837.7062	7.747389	20.00308	20.00996	-2.8422E-5
12.04584	838.8809	7.748892	20.01962	19.99305	-3.9351E-5
12.06250	840.0599	7.748608	19.99667	20.00432	6.63877E-5
12.07916	841.2336	7.747874	20.00243	20.00678	6.88065E-4
12.09584	842.4071	7.747461	19.99996	20.01666	.001428296
12.11250	843.5819	7.747430	19.99709	19.98611	.001782652
12.12916	844.7580	7.747144	20.00969	19.97588	9.68025E-4
12.14583	845.9459	7.746765	20.00378	20.00792	5.69731E-5
12.16250	847.1297	7.747049	19.99246	20.01019	-4.9584E-4
12.17917	848.2984	7.747410	19.98520	20.00862	-9.4404E-4
12.19583	849.4634	7.747692	19.99552	19.99308	-1.6529E-3
12.21250	850.6329	7.747754	20.00338	20.01796	-1.9200E-3
12.22917	851.7970	7.747809	20.00293	19.99487	-1.4144E-3
12.24584	852.9649	7.748032	20.00484	19.99478	-7.3881E-4
12.26250	854.1293	7.748707	19.99696	19.98109	-2.0133E-4
12.27916	855.3062	7.748675	20.00383	19.99485	2.28034E-4
12.29584	856.4656	7.748126	19.99900	19.99301	4.99525E-4
12.31250	857.6355	7.747772	19.98674	20.00858	6.64198E-4
12.32916	858.8113	7.747696	19.99761	20.00297	8.13461E-4
12.34584	859.9891	7.747540	20.00032	19.99880	5.52030E-4
12.36250	861.1670	7.747712	20.00639	19.99820	-2.4926E-4
12.37916	862.3456	7.748006	19.98889	20.00083	-7.1183E-4
12.39583	863.5242	7.747960	20.00509	19.99324	-9.2530E-4
12.41250	864.7001	7.747784	20.00927	20.00220	-1.2606E-3
12.42917	865.8714	7.748419	19.99170	20.00314	-2.3098E-3
12.44583	867.0468	7.748430	19.99168	20.02048	-3.3779E-3
12.46250	868.2242	7.748407	20.01066	20.00114	-4.4208E-3
12.47917	869.3968	7.748690	20.00835	19.99230	-5.0565E-3
12.49584	870.5670	7.750612	20.01099	20.00882	-5.4927E-3
12.51250	871.7375	7.751329	19.99500	20.01034	-6.4399E-3
12.52916	872.9101	7.751929	19.98933	20.01638	-7.6106E-3
12.53750	873.4972	7.751954	20.00030	19.99329	-7.8254E-3